<?xml version="1.0" encoding="utf-8"?>
<robot xmlns:xacro="http://www.ros.org/wiki/xacro" name="hand">
  <!-- safety_distance: Minimum safety distance in [m] by which the collision volumes are expanded and which is enforced during robot motions -->
  <xacro:macro name="hand" params="connected_to:='' ns:='' rpy:='0 0 0' xyz:='0 0 0' safety_distance:=0">
    <xacro:unless value="${connected_to == ''}">
      <joint name="${ns}_hand_joint" type="fixed">
        <parent link="${connected_to}"/>
        <child link="${ns}_hand"/>
        <origin xyz="${xyz}" rpy="${rpy}"/>
      </joint>
    </xacro:unless>
    <link name="${ns}_hand">
      <inertial>
        <origin xyz="-0.0000376 0.0119128 0.0207260" rpy="0 0 0"/>
        <mass value="0.6544"/>
        <inertia ixx="0.00186" ixy="0.00000" ixz="0.00000" iyy="0.00030" iyz="-0.00002" izz="0.00174"/>
      </inertial>
      <visual>
        <geometry>
          <mesh filename="package://franka_description/meshes/visual/hand.dae"/>
        </geometry>
      </visual>
      <collision>
        <origin xyz="0 0 0.04" rpy="0 ${pi/2} ${pi/2}"/>
        <geometry>
          <cylinder radius="${0.04+safety_distance}" length="0.1" />
        </geometry>
      </collision>
      <collision>
        <origin xyz="0 -0.05 0.04" rpy="0 0 0"/>
        <geometry>
          <sphere radius="${0.04+safety_distance}"  />
        </geometry>
      </collision>
      <collision>
        <origin xyz="0 0.05 0.04" rpy="0 0 0"/>
        <geometry>
          <sphere radius="${0.04+safety_distance}"  />
        </geometry>
      </collision>
      <collision>
        <origin xyz="0 0 0.1" rpy="0 ${pi/2} ${pi/2}"/>
        <geometry>
          <cylinder radius="${0.02+safety_distance}" length="0.1" />
        </geometry>
      </collision>
      <collision>
        <origin xyz="0 -0.05 0.1" rpy="0 0 0"/>
        <geometry>
          <sphere radius="${0.02+safety_distance}"  />
        </geometry>
      </collision>
      <collision>
        <origin xyz="0 0.05 0.1" rpy="0 0 0"/>
        <geometry>
          <sphere radius="${0.02+safety_distance}"  />
        </geometry>
      </collision>
    </link>
    <link name="${ns}_leftfinger">
      <inertial>
        <origin xyz="0 0.0152850 0.0219675" rpy="0 0 0"/>
        <mass value="0.0291"/>
        <inertia ixx="0.00000849" ixy="0.00000000" ixz="0.00000000" iyy="0.00000853" iyz="-0.00000106" izz="0.00000177"/>
      </inertial>
      <visual>
        <geometry>
          <mesh filename="package://franka_description/meshes/visual/finger.dae"/>
        </geometry>
      </visual>
    </link>
    <link name="${ns}_rightfinger">
      <inertial>
        <origin xyz="0 0.0152850 0.0219675" rpy="0 0 0"/>
        <mass value="0.0291"/>
        <inertia ixx="0.00000849" ixy="0.00000000" ixz="0.00000000" iyy="0.00000853" iyz="-0.00000106" izz="0.00000177"/>
      </inertial>
      <visual>
        <origin xyz="0 0 0" rpy="0 0 ${pi}"/>
        <geometry>
          <mesh filename="package://franka_description/meshes/visual/finger.dae"/>
        </geometry>
      </visual>
   </link>
    <joint name="${ns}_finger_joint1" type="prismatic">
      <parent link="${ns}_hand"/>
      <child link="${ns}_leftfinger"/>
      <origin xyz="0 0 0.0584" rpy="0 0 0"/>
      <axis xyz="0 1 0"/>
      <limit effort="20" lower="0.0" upper="0.04" velocity="0.2"/>
    </joint>
    <joint name="${ns}_finger_joint2" type="prismatic">
      <parent link="${ns}_hand"/>
      <child link="${ns}_rightfinger"/>
      <origin xyz="0 0 0.0584" rpy="0 0 0"/>
      <axis xyz="0 -1 0"/>
      <limit effort="20" lower="0.0" upper="0.04" velocity="0.2"/>
      <mimic joint="${ns}_finger_joint1" />
    </joint>
  </xacro:macro>
</robot>
